try {
    //Test code
alert(' Try Function');
alert (x);
alert(' Again Try Function');
   
} catch (error) {
    //Handle error

    alert('Inside Catch block');

    console.log('Catch')
console.log(error);


}